Workbook

Sheet Dashboard
A1: SALES DASHBOARD
A2: Sample sales data · Jan 2025 – Dec 2025 · 1,507 transactions · All figures computed from the Data sheet
A4: Total Revenue | C4: Total Profit | E4: Total Orders | G4: Avg Order Value | I4: Profit Margin | K4: Best Region
A5: 561379.36 | C5: 218609.36 | E5: 1500 | G5: 374.25291 | I5: 0.38941467 | K5: North
A62: Revenue by Region | E62: Top 5 Products
A63: Region | B63: Revenue | C63: Share % | E63: Product | F63: Revenue | G63: Units
A64: =Summary!A19 | B64: =Summary!B19 | C64: =Summary!E19 | E64: =Summary!A37 | F64: =Summary!B37 | G64: =Summary!C37
A65: =Summary!A20 | B65: =Summary!B20 | C65: =Summary!E20 | E65: =Summary!A38 | F65: =Summary!B38 | G65: =Summary!C38
A66: =Summary!A21 | B66: =Summary!B21 | C66: =Summary!E21 | E66: =Summary!A39 | F66: =Summary!B39 | G66: =Summary!C39
A67: =Summary!A22 | B67: =Summary!B22 | C67: =Summary!E22 | E67: =Summary!A40 | F67: =Summary!B40 | G67: =Summary!C40
A68: =Summary!A23 | B68: =Summary!B23 | C68: =Summary!E23 | E68: =Summary!A41 | F68: =Summary!B41 | G68: =Summary!C41

Sheet Data
A1: Order ID | B1: Order Date | C1: Customer ID | D1: Customer Name | E1: Product ID | F1: Product Name | G1: Category | H1: Quantity | I1: Unit Price | J1: Unit Cost | K1: Discount | L1: Region | M1: Sales Representative | N1: Revenue | O1: Profit
A2: ORD-1000 | B2: 46003 | C2: C-010 | D2: Divya Sharma | E2: P-019 | F2: Laptop Stand | G2: Accessories | H2: 1 | I2: 59 | J2: 24 | K2: 0.05 | L2: North | M2: Rep 6 | N2: =H2*I2*(1-K2) | O2: =N2-H2*J2
A3: ORD-1001 | B3: 45954 | C3: C-081 | D3: Ananya Rao | E3: P-011 | F3: Desk Lamp | G3: Furniture | H3: 1 | I3: 39 | J3: 15 | K3: 0.15 | L3: East | M3: Rep 7 | N3: =H3*I3*(1-K3) | O3: =N3-H3*J3
A4: ORD-1002 | B4: 45768 | C4: C-045 | D4: Neha Kulkarni | E4: P-013 | F4: Notebook Set | G4: Office Supplies | H4: 1 | I4: 19.99 | J4: 7 | K4: 0 | L4: South | M4: Rep 1 | N4: =H4*I4*(1-K4) | O4: =N4-H4*J4
A5: ORD-1003 | B5: 45832 | C5: C-048 | D5: Kavya Das | E5: P-023 | F5: External SSD 1TB | H5: 3 | I5: 119 | J5: 68 | K5: 0 | L5: West | M5: Rep 8 | N5: =H5*I5*(1-K5) | O5: =N5-H5*J5
A6: ORD-1004 | B6: 45957 | C6: C-058 | D6: Aditya Menon | E6: P-004 | F6: 4K Monitor 27in | G6: Electronics | H6: 10 | I6: 329 | J6: 210 | K6: 0.05 | L6: North | M6: Rep 7 | N6: =H6*I6*(1-K6) | O6: =N6-H6*J6
A7: ORD-1005 | B7: 45708 | C7: C-106 | D7: Manish Gupta | E7: P-023 | F7: External SSD 1TB | G7: Accessories | H7: 2 | I7: 119 | J7: 68 | K7: 0 | L7: South | M7: Rep 5 | N7: =H7*I7*(1-K7) | O7: =N7-H7*J7
A8: ORD-1006 | B8: 45923 | C8: C-001 | D8: Priya Agarwal | E8: P-003 | F8: Mechanical Keyboard | G8: Electronics | H8: 4 | I8: 89 | J8: 45 | K8: 0 | L8: South | M8: Rep 8 | N8: =H8*I8*(1-K8) | O8: =N8-H8*J8
A9: ORD-1007 | B9: 45833 | C9: C-039 | D9: Nikhil Khan | E9: P-012 | F9: Conference Table | G9: Furniture | H9: 5 | I9: 899 | J9: 520 | K9: 0.1 | L9: West | M9: Rep 1 | N9: =H9*I9*(1-K9) | O9: =N9-H9*J9
A10: ORD-1008 | B10: 46022 | C10: C-107 | D10: Vikram Nair | E10: P-017 | F10: Sticky Notes | G10: Office Supplies | H10: 4 | I10: 8.99 | J10: 3 | K10: 0 | L10: West | M10: Rep 6 | N10: =H10*I10*(1-K10) | O10: =N10-H10*J10
A11: ORD-1009 | B11: 45915 | C11: C-076 | D11: Neha Mehta | E11: P-024 | F11: Wireless Charger | G11: Accessories | H11: 1 | I11: 35 | J11: 13 | K11: 0.15 | L11: EAST | M11: Rep 1 | N11: =H11*I11*(1-K11) | O11: =N11-H11*J11
A12: ORD-1010 | B12: 45934 | C12: C-014 | D12: Ishita Bose | E12: P-021 | F12: Cable Set | G12: Accessories | H12: 1 | I12: 19 | J12: 6 | K12: 0.15 | L12: South | M12: Rep 3 | N12: =H12*I12*(1-K12) | O12: =N12-H12*J12
A13: ORD-1011 | B13: 45672 | C13: C-001 | D13: Priya Agarwal | E13: P-016 | F13: Stapler Pro | G13: Office Supplies | H13: 1 | I13: 22 | J13: 9 | K13: 0.05 | L13: South | M13: Rep 7 | N13: =H13*I13*(1-K13) | O13: =N13-H13*J13
A14: ORD-1012 | B14: 45756 | C14: C-106 | D14: Manish Gupta | E14: P-006 | F14: Noise-Cancelling Headphones | G14: ELECTRONICS | H14: 3 | I14: 199 | J14: 110 | K14: 0.15 | L14: South | M14: Rep 1 | N14: =H14*I14*(1-K14) | O14: =N14-H14*J14
A15: ORD-1013 | B15: 45927 | C15: C-104 | D15: Priya Iyer | E15: P-019 | F15: Laptop Stand | G15: Accessories | H15: 1 | I15: 59 | J15: 24 | K15: 0 | L15: South | M15: Rep 1 | N15: =H15*I15*(1-K15) | O15: =N15-H15*J15
A16: ORD-1014 | B16: 45856 | C16: C-093 | D16: Sanjay Gupta | E16: P-014 | F16: Gel Pen Pack | G16: Office Supplies | H16: 4 | I16: 12.5 | J16: 4 | K16: 0 | L16: South | M16: Rep 7 | N16: =H16*I16*(1-K16) | O16: =N16-H16*J16
A17: ORD-1015 | B17: 45738 | C17: C-035 | D17: Divya Nair | E17: P-018 | F17: Desk Organiser | G17: Office Supplies | H17: 2 | I17: 27 | J17: 10 | K17: 0.2 | L17: West | M17: Rep 5 | N17: =H17*I17*(1-K17) | O17: =N17-H17*J17
A18: ORD-1016 | B18: 45680 | C18: C-073 | D18: Sanjay Iyer | E18: P-001 | F18: Laptop Pro 14 | G18: Electronics | H18: 4 | I18: 899 | J18: 620 | K18: 0.05 | L18: North | M18: Rep 4 | N18: =H18*I18*(1-K18) | O18: =N18-H18*J18
A19: ORD-1017 | B19: 45695 | C19: C-021 | D19: Karan Bose | E19: P-005 | F19: USB-C Hub | G19: Electronics | H19: 10 | I19: 45 | J19: 18 | L19: South | M19: Rep 7 | N19: =H19*I19*(1-K19) | O19: =N19-H19*J19
A20: ORD-1018 | B20: 45904 | C20: C-067 | D20: Aarav Khan | E20: P-011 | F20: Desk Lamp | G20: Furniture | H20: 5 | I20: 39 | J20: 15 | K20: 0 | L20: North | M20: Rep 4 | N20: =H20*I20*(1-K20) | O20: =N20-H20*J20
A21: ORD-1019 | B21: 45928 | C21: C-076 | D21: Neha Mehta | E21: P-014 | F21: Gel Pen Pack | G21: Office Supplies | H21: 5 | I21: 12.5 | J21: 4 | K21: 0 | L21: North | M21: Rep 5 | N21: =H21*I21*(1-K21) | O21: =N21-H21*J21
A22: ORD-1020 | B22: 45819 | C22: C-058 | D22: Aditya Menon | E22: P-004 | F22: 4K Monitor 27in | G22: Electronics | H22: 1 | I22: 329 | J22: 210 | K22: 0 | L22: North | M22: Rep 1 | N22: =H22*I22*(1-K22) | O22: =N22-H22*J22
A23: ORD-1021 | B23: 45828 | C23: C-073 | D23: Sanjay Iyer | E23: P-008 | F23: Ergonomic Chair | G23: Furniture | H23: 2 | I23: 299 | J23: 160 | K23: 0 | L23: North | M23: Rep 4 | N23: =H23*I23*(1-K23) | O23: =N23-H23*J23
A24: ORD-1022 | B24: 45748 | C24: C-070 | D24: Aarav Bose | E24: P-015 | F24: Printer Paper A4 | G24: Office Supplies | H24: 1 | I24: 24 | J24: 11 | K24: 0 | L24: North | M24: Rep 4 | N24: =H24*I24*(1-K24) | O24: =N24-H24*J24
A25: ORD-1023 | B25: 45751 | C25: C-067 | D25: Aarav Khan | E25: P-012 | F25: Conference Table | G25: Furniture | H25: 2 | I25: 899 | J25: 520 | K25: 0.05 | L25: North | M25: Rep 6 | N25: =H25*I25*(1-K25) | O25: =N25-H25*J25
A26: ORD-1024 | B26: 45939 | C26: C-040 | D26: Divya Chopra | E26: P-006 | F26: Noise-Cancelling Headphones | G26: Electronics | H26: 2 | I26: 199 | J26: 110 | K26: 0 | L26: South | M26: Rep 5 | N26: =H26*I26*(1-K26) | O26: =N26-H26*J26
A27: ORD-1025 | B27: 45802 | C27: C-060 | D27: Neha Pillai | E27: P-016 | F27: Stapler Pro | G27: Office Supplies | H27: 3 | I27: 22 | J27: 9 | K27: 0.15 | L27: West | M27: Rep 8 | N27: =H27*I27*(1-K27) | O27: =N27-H27*J27
A28: ORD-1026 | B28: 45856 | C28: C-061 | D28: Sanjay Desai | E28: P-007 | F28: Standing Desk | G28: Furniture | H28: 1 | I28: 449 | J28: 260 | K28: 0.1 | L28: West | M28: Rep 4 | N28: =H28*I28*(1-K28) | O28: =N28-H28*J28
A29: ORD-1027 | B29: 45706 | C29: C-005 | D29: Ritu Joshi | E29: P-012 | F29: Conference Table | G29: Furniture | H29: 4 | I29: 899 | J29: 520 | K29: 0 | L29: West | M29: Rep 3 | N29: =H29*I29*(1-K29) | O29: =N29-H29*J29
A30: ORD-1028 | B30: 45793 | C30: C-018 | D30: Sanjay Sharma | E30: P-018 | F30: Desk Organiser | G30: Office Supplies | H30: 3 | I30: 27 | J30: 10 | K30: 0 | L30: East | M30: Rep 4 | N30: =H30*I30*(1-K30) | O30: =N30-H30*J30
A31: ORD-1029 | B31: 45981 | C31: C-046 | D31: Ananya Sharma | E31: P-020 | F31: Phone Case | G31: Accessories | H31: 1 | I31: 24.99 | J31: 8 | K31: 0.05 | L31: West | M31: Rep 1 | N31: =H31*I31*(1-K31) | O31: =N31-H31*J31
... A42: ORD-1040 | B42: 45854 | C42: C-063 | D42: Karan Verma | E42: P-013 | F42: Notebook Set | G42: Office Supplies | H42: 1 | I42: 19.99 | J42: 7 | K42: 0.15 | L42: North | M42: Rep 6 | N42: =H42*I42*(1-K42) | O42: =N42-H42*J42
A43: ORD-1041 | B43: 45732 | C43: C-044 | D43: Sneha Kulkarni | E43: P-016 | F43: Stapler Pro | H43: 1 | I43: 22 | J43: 9 | K43: 0 | L43: North | M43: Rep 8 | N43: =H43*I43*(1-K43) | O43: =N43-H43*J43
A44: ORD-1042 | B44: 45836 | C44: C-039 | D44: Nikhil Khan | E44: P-004 | F44: 4K Monitor 27in | G44: Electronics | H44: 1 | I44: 329 | J44: 210 | K44: 0 | L44: West | M44: Rep 2 | N44: =H44*I44*(1-K44) | O44: =N44-H44*J44
A45: ORD-1043 | B45: 45903 | C45: C-119 | D45: Divya Das | E45: P-017 | F45: Sticky Notes | G45: Office Supplies | H45: 2 | I45: 8.99 | J45: 3 | K45: 0 | L45: South | M45: Rep 7 | N45: =H45*I45*(1-K45) | O45: =N45-H45*J45
A46: ORD-1044 | B46: 45995 | C46: C-089 | D46: Varun Mehta | E46: P-007 | F46: Standing Desk | G46: Furniture | H46: 3 | I46: 449 | J46: 260 | K46: 0.1 | L46: North | M46: Rep 1 | N46: =H46*I46*(1-K46) | O46: =N46-H46*J46
A47: ORD-1045 | B47: 45940 | C47: C-054 | D47: Varun Agarwal | E47: P-003 | F47: Mechanical Keyboard | G47: Electronics | H47: 2 | I47: 89 | J47: 45 | K47: 0.05 | L47: North | M47: Rep 8 | N47: =H47*I47*(1-K47) | O47: =N47-H47*J47
A48: ORD-1046 | B48: 46018 | C48: C-037 | D48: Priya Patel | E48: P-020 | F48: Phone Case | G48: Accessories | H48: 3 | I48: 24.99 | J48: 8 | K48: 0 | L48: West | M48: Rep 1 | N48: =H48*I48*(1-K48) | O48: =N48-H48*J48
A49: ORD-1047 | B49: 45674 | C49: C-097 | D49: Varun Menon | E49: P-003 | F49: Mechanical Keyboard | G49: Electronics | H49: 2 | I49: 89 | J49: 45 | K49: 0.2 | L49: North | M49: Rep 4 | N49: =H49*I49*(1-K49) | O49: =N49-H49*J49
A50: ORD-1048 | B50: 46016 | C50: C-053 | D50: Rohan Nair | E50: P-002 | F50: Wireless Mouse | G50: Electronics | H50: 1 | I50: 29.99 | J50: 12 | K50: 0 | L50: East | M50: Rep 5 | N50: =H50*I50*(1-K50) | O50: =N50-H50*J50
...

Sheet Summary
A1: Monthly trend
A2: Month | B2: Revenue | C2: Profit | D2: Orders
A3: 45658 | B3: 53131.904 | C3: 20706.904 | D3: 117
A4: 45689 | B4: 33381.321 | C4: 12308.322 | D4: 81
A5: 45717 | B5: 39075.488 | C5: 14649.488 | D5: 100
A6: 45748 | B6: 35313.989 | C6: 13634.989 | D6: 113
A7: 45778 | B7: 41114.063 | C7: 16595.063 | D7: 124
A8: 45809 | B8: 45877.577 | C8: 17632.577 | D8: 111
A9: 45839 | B9: 48376.341 | C9: 19541.341 | D9: 133
A10: 45870 | B10: 56927.075 | C10: 19952.074 | D10: 129
A11: 45901 | B11: 40741.166 | C11: 17363.165 | D11: 133
A12: 45931 | B12: 42136.658 | C12: 16412.658 | D12: 130
A13: 45962 | B13: 70041.012 | C13: 27865.013 | D13: 161
A14: 45992 | B14: 55262.764 | C14: 21947.764 | D14: 168
A17: Revenue by region
A18: Region | B18: Revenue | C18: Profit | D18: Orders | E18: Share %
A19: North | B19: 242613.9 | C19: 94325.903 | D19: 655 | E19: 43.217461
A20: South | B20: 134077.73 | C20: 50984.732 | D20: 295 | E20: 23.883624
A21: East | B21: 97980.69 | C21: 38284.69 | D21: 255 | E21: 17.453561
A22: West | B22: 86596.283 | C22: 34952.283 | D22: 293 | E22: 15.425626
A23: EAST | B23: 29.75 | C23: 16.75 | D23: 1 | E23: 0.0052994467
A26: Revenue by category
A27: Category | B27: Revenue | C27: Profit | D27: Orders
A28: Furniture | B28: 257738.1 | C28: 105738.1 | D28: 386
A29: Electronics | B29: 245885.54 | C29: 81134.545 | D29: 385
A30: Accessories | B30: 40190.91 | C30: 21395.91 | D30: 354
A31: Office Supplies | B31: 16678.354 | C31: 9997.354 | D31: 372
A32: ELECTRONICS | B32: 507.45 | C32: 177.45 | D32: 1
A35: Top 5 products by revenue
A36: Product Name | B36: Revenue | C36: Units | D36: Orders
A37: Laptop Pro 14 | B37: 138850.55 | C37: 161 | D37: 67
A38: Conference Table | B38: 109048.7 | C38: 130 | D38: 62
A39: 4K Monitor 27in | B39: 59828.65 | C39: 189 | D39: 69
A40: Standing Desk | B40: 58594.5 | C40: 136 | D40: 65
A41: Ergonomic Chair | B41: 39333.45 | C41: 136 | D41: 63
